Workbook

Sheet Attached for PAYE
A1: Payment for PAYE (Attached List)
A2: Employer Name- | I2: Diamond Palace Services Company Limited
A3: TIN - | I3: 100XXXXXX
A4: Record Number | B4: Employee Name | C4: NRC No (if) | H4: Employee Address | I4: Passport No (if) | J4: Position | K4: End Date of Period covered by Payment (DD-MM-YYYY) | L4: Tax Period | M4: Income Year | N4: Salary for Period (Kyat) | O4: Allowances claimed by Employee | P4: Amount Withheld (Kyat) | Q4: Remark
A5: 1 | B5: Thu Ya Oo | C5: 1 | D5: =IF(C5="","",IFERROR(VLOOKUP(C5,TSP_Code!$A$2:$B$15,2,FALSE),"")) -> Kachin | E5: DAPHAYA | F5: (N) | G5: 122204 | H5: N0-6/75,AyeTharYar Township,Taunngkyi | I5: - | J5: Manager | K5: 30-06-2020 | L5: JUN | M5: 2020 | N5: 2000000 | O5: 1000000 | P5: 20000
A6: 2 | B6: Myo Myo | C6: 14 | D6: =IF(C6="","",IFERROR(VLOOKUP(C6,TSP_Code!$A$2:$B$15,2,FALSE),"")) -> Ayeyarwaddy | E6: DADAYA | F6: (N) | G6: 052334 | H6: No-8,34Shwe Lann,Yangon | I6: - | J6: General Manager | K6: 30-06-2020 | L6: JUN | M6: 2020 | N6: 3000000 | O6: 1200000 | P6: 23000
D10: =IF(C10="","",IFERROR(VLOOKUP(C10,TSP_Code!$A$2:$B$15,2,FALSE),""))
D11: =IF(C11="","",IFERROR(VLOOKUP(C11,TSP_Code!$A$2:$B$15,2,FALSE),""))
D12: =IF(C12="","",IFERROR(VLOOKUP(C12,TSP_Code!$A$2:$B$15,2,FALSE),""))
D13: =IF(C13="","",IFERROR(VLOOKUP(C13,TSP_Code!$A$2:$B$15,2,FALSE),""))
D14: =IF(C14="","",IFERROR(VLOOKUP(C14,TSP_Code!$A$2:$B$15,2,FALSE),""))
D15: =IF(C15="","",IFERROR(VLOOKUP(C15,TSP_Code!$A$2:$B$15,2,FALSE),""))
D16: =IF(C16="","",IFERROR(VLOOKUP(C16,TSP_Code!$A$2:$B$15,2,FALSE),""))
D17: =IF(C17="","",IFERROR(VLOOKUP(C17,TSP_Code!$A$2:$B$15,2,FALSE),""))
D18: =IF(C18="","",IFERROR(VLOOKUP(C18,TSP_Code!$A$2:$B$15,2,FALSE),""))
D19: =IF(C19="","",IFERROR(VLOOKUP(C19,TSP_Code!$A$2:$B$15,2,FALSE),""))
D20: =IF(C20="","",IFERROR(VLOOKUP(C20,TSP_Code!$A$2:$B$15,2,FALSE),""))
D21: =IF(C21="","",IFERROR(VLOOKUP(C21,TSP_Code!$A$2:$B$15,2,FALSE),""))
... D89: =IF(C89="","",IFERROR(VLOOKUP(C89,TSP_Code!$A$2:$B$15,2,FALSE),""))

Sheet Period
B2: JAN
B3: FEB
B4: MAR
B5: APR
B6: MAY
B7: JUN
B8: JUL
B9: AUG
B10: SEP
B11: OCT
B12: NOV
B13: DEC

Sheet TSP_Code
A1: DivisionState | D1: 1 | E1: 2 | F1: 3 | G1: 4 | H1: 5 | I1: 6 | J1: 7 | K1: 8 | L1: 9 | M1: 10 | N1: 11 | O1: 12 | P1: 13 | Q1: 14
A2: 1 | B2: Kachin | D2: DAPHAYA | E2: BALAKHA | F2: BAAHNA | G2: HAKHANA | H2: AHTANA | I2: BAPANA | J2: AHPHANA | K2: AHLANA | L2: AHMAYA | M2: BALANA | N2: AHMANA | O2: AHLANA | P2: AHPANA | Q2: AHGAPA
A3: 2 | B3: Kayah | D3: HAPANA | E3: DAMASA | F3: BAGALA | G3: HTATALA | H3: AHYATA | I3: HTAWANA | J3: AHTANA | K3: GAGANA | L3: AHMAZA | M3: KAHTANA | N3: BATHATA | O3: AHSANA | P3: AHTANA | Q3: AHMANA
A4: 3 | B4: Kayin | D4: KAMANA | E4: LAKANA | F4: BAKALA | G4: KAKHANA | H4: BAMANA | I4: KALAAH | J4: DAOUNA | K4: HTALANA | L4: AUTATHA | M4: KAKHAMA | N4: GAMANA | O4: BAHANA | P4: AHTHAYA | Q4: AHMATA
A5: 4 | B5: Chin | D5: KAPATA | E5: MASANA | F5: BATHASA | G5: KAPALA | H5: BATALA | I5: KASANA | J5: HTATAPA | K5: KAHTANA | L5: DAKHATHA | M5: KAMAYA | N5: KAPHANA | O5: BATAHTA | P5: HAHANA | Q5: BAKALA
A6: 5 | B6: Sagaing | D6: KHABADA | E6: PHASANA | F6: KADANA | G6: MATANA | H6: DAHANA | I6: KATHANA | J6: KAKANA | K6: KAMANA | L6: KAMANA | M6: KHASANA | N6: KATALA | O6: DAGAMA | P6: HAMANA | Q6: DADAYA
A7: 6 | B7: Tanintharyi | D7: KHALAPHA | E7: PHAYASA | F7: KAKAYA | G7: MATAPA | H7: DAPAYA | I7: KAYAYA | J7: KAPAKA | K7: KHAMANA | L7: KAPATA | M7: KHAZANA | N7: KATANA | O7: DAGANA | P7: HAPANA | Q7: DANAPHA
A8: 7 | B8: Bago | D8: KHAPHANA | E8: YATANA | F8: KAMAMA | G8: PALAWA | H8: HAMALA | I8: KHAMAKA | J8: KATAKHA | K8: MABANA | L8: KASANA | M8: LAMANA | N8: MAAHNA | O8: DAGASA | P8: HAPATA | Q8: HAKAKA
A9: 8 | B9: Magwe | D9: LAGANA | E9: YATHANA | F9: KASAKA | G9: PHALANA | H9: HSAMAYA | I9: LALANA | J9: KATATA | K9: MAHTANA | L9: KHAAHZA | M9: MADANA | N9: MAAHTA | O9: DAGATA | P9: KAHANA | Q9: HATHATA
A10: 9 | B10: Mandalay | D10: MAKANA | F10: LABANA | G10: SAMANA | H10: HTAKHANA | I10: MAAHNA | J10: KAWANA | K10: MAKANA | L10: KHAMASA | M10: MALAMA | N10: MAOUNA | O10: DAGAYA | P10: KAKANA | Q10: KAKAHTA
A11: 10 | B11: Mon | D11: MAKATA | F11: LATHANA | G11: TATANA | H11: HTAPAKHA | I11: MAAHYA | J11: LAPATA | K11: MALANA | L11: LAWANA | M11: PAMANA | N11: MAPANA | O11: DALANA | P11: KAKHANA | Q11: KAKANA
A12: 11 | B12: Rakhine | D12: MAKHABA | F12: MAWATA | G12: TAZANA | H12: KABALA | I12: MAMANA | J12: MADANA | K12: MAMANA | L12: MAHAMA | M12: THAHTANA | N12: MAPATA | O12: DAPANA | P12: KALADA | Q12: KAKHANA
A13: 12 | B13: Yangon | D13: MALANA | F13: PAKANA | G13: YAKHADA | H13: KALAHTA | I13: MATANA | J13: MALANA | K13: MATANA | L13: MAHTALA | M13: THAPHAYA | N13: PATANA | O13: HTATAPA | P13: KALAHTA | Q13: KALANA
A14: 13 | B14: Shan | D14: MAMANA | F14: PHAAHNA | G14: YAZANA | H14: KALANA | I14: NGAYAKA | J14: MANYANA | K14: MATHANA | L14: MAKANA | M14: YAMANA | N14: PANAKA | O14: KAKAKA | P14: KALANA | Q14: KAPANA
A15: 14 | B15: Ayeyarwaddy | D15: MANYANA | F15: PHAPANA | H15: KALATA | I15: PAKAMA | J15: NATALA | K15: NAMANA | L15: MAKHANA | N15: PANATA | O15: KAKHAKA | P15: KALATA | Q15: LAMANA
D16: MASANA | F16: SAKALA | H16: KALAWA | I16: PALANA | J16: NYALAPA | K16: NGAPHANA | L16: MALANA | N16: SATANA | O16: KAMANA | P16: KAMANA | Q16: LAPATA
D17: NAMANA | F17: THATAKA | H17: KAMANA | I17: PALATA | J17: PAKHANA | K17: PAKHAKA | L17: MAMANA | N17: TAKANA | O17: KAMATA | P17: KATALA | Q17: MAAHNA
D18: PANADA | F18: THATANA | H18: KANANA | I18: TANATHA | J18: PAKHATA | K18: PAMANA | L18: MANAMA | N18: TAPAWA | O18: KAMAYA | P18: KATANA | Q18: MAAHPA
D19: PATAAH | F19: WALAMA | H19: KATHANA | I19: TATHAYA | J19: PAMANA | K19: PAPHANA | L19: MANATA | N19: THATANA | O19: KATANA | P19: KATATA | Q19: MAMAKA
D20: PAWANA | F20: YAYATHA | H20: KHAOUNA | I20: THAYAKHA | J20: PANAKA | K20: SAKANA | L20: MATAYA | N20: YABANA | O20: KATATA | P20: KATHANA | Q20: MAMANA
D21: PHAKANA | H21: KHAOUTA | I21: YAPHANA | J21: PATALA | K21: SALANA | L21: MATHANA | N21: YATHATA | O21: KHAYANA | P21: KHALANA | Q21: NGAPATA
D22: SABANA | H22: KHAPANA | J22: PATANA | K22: SAMANA | L22: MAYAMA | N22: MATANA | O22: LAKANA | P22: KHAYAHA | Q22: NGASANA
D23: SADANA | H23: KHATANA | J23: PATASA | K23: SAPAWA | L23: MAYATA | O23: LAMANA | P23: LAKANA | Q23: NGATHAKHA
D24: SALANA | H24: LAHANA | J24: PATATA | K24: SAPHANA | L24: NAHTAKA | O24: LAMATA | P24: LAKHANA | Q24: NGAYAKA
D25: SAPABA | H25: LAYANA | J25: PHAMANA | K25: SATAYA | L25: NGATHAYA | O25: LATHANA | P25: LAKHATA | Q25: NYATANA
D26: TANANA | H26: MAKANA | J26: TANGANA | K26: TATAKA | L26: NGAZANA | O26: LATHAYA | P26: LALANA | Q26: PASALA
D27: WAMANA | H27: MALANA | J27: THAKANA | K27: THAYANA | L27: NYAOUNA | O27: MABANA | P27: LAYANA | Q27: PATANA
D28: YABAYA | H28: MAMANA | J28: THANAPA | K28: YAMANA | L28: PABANA | O28: MAGADA | P28: MABANA | Q28: PATHAAH
D29: YAKANA | H29: MAMATA | J29: THASANA | K29: YANAKHA | L29: PABATHA | O29: MAGATA | P29: MAHAYA | Q29: PATHANA
H30: MAPALA | J30: THAWATA | K30: YASAKA | L30: PAKAKHA | O30: MAYAKA | P30: MAHTANA | Q30: PATHAYA
H31: MATHANA | J31: WAMANA | L31: PAMANA | O31: OUKAMA | P31: MAHTATA | Q31: PHAPANA
H32: MAYANA | J32: YAKANA | L32: PAOULA | O32: OUKATA | P32: MAKANA | Q32: THAPANA
H33: NAYANA | J33: YATANA | L33: PATHAKA | O33: PABATA | P33: MAKATA | Q33: WAKHAMA
H34: NGAZANA | J34: YATAYA | L34: SAKANA | O34: PAZATA | P34: MAKHANA | Q34: YAKANA
H35: PALABA | J35: ZAKANA | L35: SAKATA | O35: SAKAKHA | P35: MAKHATA | Q35: YATHAYA
H36: PALANA | L36: TAKANA | O36: SAKANA | P36: MALANA | Q36: ZALANA
H37: PASANA | L37: TAKATA | O37: SAKHANA | P37: MALATA
H38: PHAPANA | L38: TATAOU | O38: TAKANA | P38: MAMAHTA
H39: SAKANA | L39: TATHANA | O39: TAMANA | P39: MAMANA
H40: HSALAKA | L40: THAPAKA | O40: TATAHTA | P40: MAMATA
...
